Workbook

Sheet Master
A1: Year | B1: SH | C1: Project Name | D1: Department | E1: Risk Area | F1: Descriptions | G1: Code | H1: Bobot | I1: Kadar | J1: Nilai
A2: 2022 | B2: SH1 | C2: Century21 | D2: Departemen Franchise Development Department (FDD) | E2: Kelengkapan dokumen sebagai persyaratan administratif bagi MB Baru, MB Renewal, dan MB yang tutup. (Kelengkapan dokumen yang harus dipenuhi oleh setiap MB baik yang baru maupun yang masih aktif adalah Akte Pendirian PT/CV (badan Usaha), KTP, SIUP, TDP, NPWP, dan Pengesahan Menkeh; sedangkan untuk MB yang ingin mengakhiri kerja sama harus mengirimkan surat pengakhiran kerja sama ke pihak C21) | F2: Berdasarkan pemeriksaan atas perjanjian Waralaba Century21 Primary Network, ditemukan PKS belum ditandatangani oleh pihak Franchisor dan Franchisee berselang 397 hari sejak PKS dibuat s/d cut off audit 24 Mar’22; Klausul pada PKS menyebutkan ada Dana Periklanan Nasional namun dalam penerapannya tidak ada. (Temuan ulangan) | G2: F | H2: 2 | I2: 2.5 | J2: 5
A3: 2022 | B3: SH1 | C3: Century21 | D3: Departemen Franchise Development Department (FDD) | E3: Kelengkapan dokumen sebagai persyaratan administratif bagi MB Baru, MB Renewal, dan MB yang tutup. (Kelengkapan dokumen yang harus dipenuhi oleh setiap MB baik yang baru maupun yang masih aktif adalah Akte Pendirian PT/CV (badan Usaha), KTP, SIUP, TDP, NPWP, dan Pengesahan Menkeh; sedangkan untuk MB yang ingin mengakhiri kerja sama harus mengirimkan surat pengakhiran kerja sama ke pihak C21) | F3: Berdasarkan pemeriksaan atas perjanjian kerjasama pemasaran antara PT Kota Podomoro Tenjo Sejahtera (Developer) dengan Century21 Indonesia (Lead Agent), ditemukan Tidak ada Perjanjian atau Internal Memo yang menjelaskan fee konsorsium sebesar 0.5% harus dibagi rata antara PT. Fitria Kusuma Persada (Century21), PT Properti Maxima International (Promex) dan PT Era Graharealty Tbk (ERA) | G3: F | H3: 2 | I3: 2.5 | J3: 5
A4: 2022 | B4: SH1 | C4: Century21 | D4: Departemen Franchise Development Department (FDD) | E4: Renewal MB (Setiap MB yang renewal harus sesuai dengan price list yang ada, bila tidak sesuai dengan price list yang ada, maka harus mendapatkan persetujuan dari Direktur) | G4: NF | H4: 0 | I4: 0 | J4: 0
A5: 2022 | B5: SH1 | C5: Century21 | D5: Departemen Franchise Development Department (FDD) | E5: Nilai Franchise fee, Royalty, Annually fee, NAF (Setiap nilai maupun ketentuan dari Franchise fee, Royalty, Annually fee, NAF harus sesuai dengan price list yang ada, bila tidak sesuai dengan price list yang ada, maka harus mendapatkan persetujuan dari Direktur) | G5: NF | H5: 0 | I5: 0 | J5: 0
A6: 2022 | B6: SH1 | C6: Century21 | D6: Departemen Franchise Development Department (FDD) | E6: Lokasi penyebaran MB (Penyebaran lokasi dapat di bandingkan dangan jumlah penyebaran franchise broker pesaing (ERA, Ray white dll) | G6: NF | H6: 0 | I6: 0 | J6: 0
A7: 2022 | B7: SH1 | C7: Century21 | D7: Departemen Franchise Support Development (FSD) | E7: Eksklusif Listing, Open Listing dan PJP | G7: NF | H7: 0 | I7: 0 | J7: 0
A8: 2022 | B8: SH1 | C8: Century21 | D8: Departemen Franchise Support Development (FSD) | E8: Kurang lengkapnya informasi yang disajikan pada laporan transaksi | G8: NF | H8: 0 | I8: 0 | J8: 0
A9: 2022 | B9: SH1 | C9: Century21 | D9: Departemen Franchise Support Development (FSD) | E9: Komisi yang diterima oleh C21 (komisi diberikan atas semua unit yang terjual dan sesuai dengan ketentuan yang berlaku) | G9: NF | H9: 0 | I9: 0 | J9: 0
A10: 2022 | B10: SH1 | C10: Century21 | D10: Departemen Franchise Support Development (FSD) | E10: Transaksi referral dan co-broking (Setiap transaksi referral dan co-broking harus mempunyai surat pernyataan dari MB yang mempunyai transaksi tsb) | G10: NF | H10: 0 | I10: 0 | J10: 0
A11: 2022 | B11: SH1 | C11: Century21 | D11: Departemen Franchise Support Development (FSD) | E11: Pengelolaan barang souvenir (Pengelolaan barang souvenir harus mempunyai kartu stock persediaan, dan mutasi keluar masuk barang harus ada bukti terima/keluar barang yang di setujui oleh pihak yang berwenang) | G11: NF | H11: 0 | I11: 0 | J11: 0
A12: 2022 | B12: SH1 | C12: Century21 | D12: Departemen Franchise Support Development (FSD) | E12: Training (Memastikan setiap kebijakan training mendapat persetujuan dari pihak berwenang, administrasi pendaftaran training sudah lengkap, penagihan biaya training dilakukan dengan baik) | G12: NF | H12: 0 | I12: 0 | J12: 0
A13: 2022 | B13: SH1 | C13: Century21 | D13: Departemen Franchise Support Development (FSD) | E13: Pemberian Award kepada MB dan MA (award yang didapat sesuai dengan pencapaian oleh MB/MA) | G13: NF | H13: 0 | I13: 0 | J13: 0
A14: 2022 | B14: SH1 | C14: Century21 | D14: Departemen Franchise Support Development (FSD) | E14: Kegiatan pembelian (Pembelian barang-barang dilakukan oleh purchasing; setiap pembelian dilakukan perbandingan minimal 3 supplier; setiap permintaan barang harus didahului oleh PR dan disetujui oleh pihak yang berwenang; setiap pembelian harus mempunyai PO dan disetujui oleh pihak yang berwenang) | G14: NF | H14: 0 | I14: 0 | J14: 0
A15: 2022 | B15: SH1 | C15: Century21 | D15: Departemen ICD | E15: Software yang ada (setiap MB diberikan paket software dan diberikan pelatihan cara menggunakannya) | G15: NF | H15: 0 | I15: 0 | J15: 0
... A17: 2022 | B17: SH1 | C17: Century21 | D17: Departemen ICD | E17: Monitoring Maintenace Website Century | G17: NF | H17: 0 | I17: 0 | J17: 0
A18: 2022 | B18: SH1 | C18: Century21 | D18: Departemen Finance And Accounting Departement (FAD) | E18: Cash dan Bank Management (dilakukan opname berkala dan didukung Berita Acara, setiap mutasi yang terjadi harus dicatat dan diupdate, kas bon dicatat terpisah dari buku kas harian dan harus dimonitor batas pertanggung jawabannya) | F18: Berdasarkan cash opname pada tanggal 17 Mar’22, ditemukan Reimbursement kas kecil ditransfer ke rekening pribadi PIC (Admin Marketing); Belum dilakukan cash opname rutin secara berkala yang dilengkapi dengan Berita Acara Opname yang ditandatangani oleh Finance & Accounting Manager | G18: F | H18: 2 | I18: 3 | J18: 6
A19: 2022 | B19: SH1 | C19: Century21 | D19: Departemen Finance And Accounting Departement (FAD) | E19: Cash dan Bank Management (dilakukan opname berkala dan didukung Berita Acara, setiap mutasi yang terjadi harus dicatat dan diupdate, kas bon dicatat terpisah dari buku kas harian dan harus dimonitor batas pertanggung jawabannya) | F19: Berdasarkan sample check atas 20 transaksi pembayaran menggunakan Cheque/Giro, ditemukan seluruh pembayaran untuk kasbon ditransfer ke rekening pribadi karyawan | G19: F | H19: 2 | I19: 3 | J19: 6
A20: 2022 | B20: SH1 | C20: Century21 | D20: Departemen Finance And Accounting Departement (FAD) | E20: Piutang dan Collection (aging schedule dimonitor setiap bulannya dan dikirimkan surat peringatan atas konsumen yang melakukan tunggakan) | F20: Berdasarkan sample check pembayaran tagihan atas 4 MB, ditemukan 4 MB yang pencatatan umur tunggakan di monitoring aging tidak diklasifikasikan berdasarkan urutan umur tagihan; 2 MB yang berdasarkan pemeriksaan Audit membayar bukan dari periode terlama (Temuan ulangan) | G20: F | H20: 2 | I20: 3.5 | J20: 7
A21: 2022 | B21: SH1 | C21: Century21 | D21: Departemen Finance And Accounting Departement (FAD) | E21: Piutang dan Collection (aging schedule dimonitor setiap bulannya dan dikirimkan surat peringatan atas konsumen yang melakukan tunggakan) | F21: Berdasarkan sample check pembayaran annual fee atas 56 MB, ditemukan tunggakan annual fee atas 4 MB yang belum dicatat dalam aging, di mana tunggakan tersebut hanya tercatat dalam rekap manual dengan total Rp 20,000,000 dan telah berumur berkisar 184 hari s/d 427 hari sejak tanggal jatuh tempo s/d pullout audit 18 Mar’22 | G21: F | H21: 2 | I21: 3.5 | J21: 7
A22: 2022 | B22: SH1 | C22: Century21 | D22: Departemen Finance And Accounting Departement (FAD) | E22: Internal Control Lintas Departemen (Fin Acc harus menjalankan fungsi control, bukan hanya mencatat saja) | F22: Berdasarkan full check atas 16 penerimaan sponsorship ditemukan tidak konsisten-nya pencatatan atas penerimaan sponsorship di mana di catat pada 2 Akun yaitu Akun Pendapatan Lain-lain (32.10.190) dan Akun Commision BCA (32.40.120) | G22: F | H22: 2 | I22: 4.5 | J22: 9
A23: 2022 | B23: SH1 | C23: Century21 | D23: Departemen Finance And Accounting Departement (FAD) | E23: Internal Control Lintas Departemen (Fin Acc harus menjalankan fungsi control, bukan hanya mencatat saja) | F23: Berdasarkan pemeriksaan atas investasi berupa saham yang tercantum di Neraca ditemukan kesalahan pencatatan atas penerimaan deviden tahun 2021, di mana saat penerimaan deviden tidak dicatat sebagai pendapatan deviden (kredit), melainkan dicatat pada akun RDN SAG001 (11.20.400) sehingga menyebabkan saldo pendapatan deviden dan akun RDN SAG001 understated sebesar Rp 15,520,590 (Temuan ulangan) | G23: F | H23: 2 | I23: 4.5 | J23: 9
A24: 2022 | B24: SH1 | C24: Century21 | D24: Departemen Finance And Accounting Departement (FAD) | E24: Internal Control Lintas Departemen (Fin Acc harus menjalankan fungsi control, bukan hanya mencatat saja) | F24: Berdasarkan analisa account Piutang Lainnya (No.Akun: 11.30.990) per 31 Des’21, ditemukan saldo akun Piutang Lainnya bersaldo minus sebesar Rp 39,332,074 (Sagotra Usaha) | G24: F | H24: 2 | I24: 4.5 | J24: 9
A25: 2022 | B25: SH1 | C25: Century21 | D25: Departemen Finance And Accounting Departement (FAD) | E25: Internal Control Lintas Departemen (Fin Acc harus menjalankan fungsi control, bukan hanya mencatat saja) | F25: Saldo Piutang lainnya per Des’19 sebesar Rp 1,691,673,996 merupakan saldo bawaan kumulatif s/d Dec’19 yang tidak terinci secara detail sehingga saldo Des’20 menjadi sebesar Rp. 134,588,124 (Fitria Kusuma Persada) | G25: F | H25: 2 | I25: 4.5 | J25: 9
A26: 2022 | B26: SH1 | C26: Century21 | D26: Departemen Finance And Accounting Departement (FAD) | E26: Internal Control Lintas Departemen (Fin Acc harus menjalankan fungsi control, bukan hanya mencatat saja) | F26: Berdasarkan pemeriksaan atas pengakuan sewa ruko sebesar Rp 110,000,000 (termasuk PPN) ditemukan kesalahan pencatatan atas penerimaan sewa ruko, di mana penerimaan dicatat pada akun Pendapatan Lain-lain padahal seharusnya dicatat pada akun Sewa Diterima Dimuka (Temuan ulangan) | G26: F | H26: 2 | I26: 4.5 | J26: 9
A27: 2022 | B27: SH1 | C27: Century21 | D27: Departemen Finance And Accounting Departement (FAD) | E27: Internal Control Lintas Departemen (Fin Acc harus menjalankan fungsi control, bukan hanya mencatat saja) | F27: Penerimaan NAF (No.Akun: 11.70.100) bersaldo kredit dan Pengeluaran NAF (No. Akun: 11.70.200) bersaldo debit dicatat pada dua akun asset yang berbeda dan tidak dilakukan offset | G27: F | H27: 2 | I27: 4.5 | J27: 9
A28: 2022 | B28: SH1 | C28: Century21 | D28: Departemen Finance And Accounting Departement (FAD) | E28: Pengelolaan dan Pengamanan Asset (Setiap Aset harus di data (nilai, tgl bln thn perolehan, jenis barang, nama barang, kode barang)) | F28: Berdasarkan full check perhitungan depresiasi atas 91 item (121 pcs) inventaris asset per 31 Des’21 ditemukan selisih perhitungan biaya penyusutan dan akumulasi penyusutan atas 21 item inventaris asset (22 pcs) antara Asset List dengan perhitungan audit di mana terdapat overstated nilai Biaya Penyusutan Inventaris Kantor sebesar Rp 1,085,522 dan Understated Akumulasi Penyusutan Inventaris Kantor yang mengakibatkan overstated nilai buku sebesar Rp 2,542,134; Selisih perhitungan Biaya Penyusutan dan Akumulasi Penyusutan Inventaris antara Trial Balance per 31 Dec’21 dengan perhitungan Audit masing-masing sebesar Rp 9,005,802 dan Rp 1,063,315 (Temuan ulangan) | G28: F | H28: 2 | I28: 4.5 | J28: 9
A29: 2022 | B29: SH1 | C29: Century21 | D29: Departemen Finance And Accounting Departement (FAD) | E29: Pengelolaan dan Pengamanan Asset (Setiap Aset harus di data (nilai, tgl bln thn perolehan, jenis barang, nama barang, kode barang)) | F29: Berdasarkan pemeriksaan atas akun MLS Software (No.Akun: 16.50.100) per 31 Dec’21 sebesar Rp 2,001,000,000, ditemukan Asset Software tersebut belum diamortisasi dan understated Rp 120,000,000 karena kesalahan pencatatan atas penerimaan sewa aplikasi di mana seharusnya diakui sebagai pendapatan namun dicatat sebagai pengurang asset. (PT Fitria Kusumapersada) | G29: F | H29: 2 | I29: 4.5 | J29: 9
... A32: 2022 | B32: SH1 | C32: Century21 | D32: Departemen Finance And Accounting Departement (FAD) | E32: Pembelanjaan Dept Purchasing (dilakukan sesuai dengan prosedur pengadaan barang yaitu dengan SPK/PO, perbandingan harga minimal 3 supplier, disetujui sesuai koridor; pengelolaan atas barang yang ada dilakukan dengan baik). | F32: Berdasarkan pemeriksaan pemeriksan pembayaran sewa mesin fotocopy atas 4 transaksi pembayaran sewa mesin fotocopy, ditemukan Dokumen Perjanjian Sewa tidak diarsip dengan baik dan tidak ada addendum perpanjangan atas sewa tersebut; Rata-rata pemakaian untuk 4 bulan hanya sebesar 1,462 lembar (37%) dari minimum pemakaian kertas; Tidak dipotongkan PPN dan PPh 23 atas sewa Mesin Fotocopy | G32: F | H32: 2 | I32: 2 | J32: 4
A33: 2022 | B33: SH1 | C33: Century21 | D33: HRD | E33: Monitoring Lembur (setiap lembur harus didukung dengan SPL yang dibuat sebelum pekerjaan lembur dijalankan/maksimal satu hari setelah lembur, disetujui atasan yang berwenang, jam kerja yang diperhitungkan sebagai lembur adalah yang lebih kecil antara absensi vs jam di SPL, jika absensi lebih besar dan memang dibutuhkan penyesuaian jam lembur maka SPL harus direvisi ulang) | G33: NF | H33: 0 | I33: 0 | J33: 0
A34: 2022 | B34: SH1 | C34: Century21 | D34: HRD | E34: Absensi (setiap karyawan harus melakukan absensi setiap harinya, apabila tidak absen harus didukung dengan form ijin/cuti/tugas kantor yang disetujui atasan ybs) | F34: Berdasarkan full check atas 21 karyawan selama bulan Okt’21, ditemukan 21 karyawan (160 hari kerja), pada system tercatat tidak absen masuk dan absen pulang namun tidak ada keterangan; Tidak terdapat pembagian hari kerja WFH dan WFO secara tertulis; 8 karyawan (27 hari kerja), di mana karyawan tersebut pada system hanya tercatat absen masuk; Selama ini tidak pernah dilakukan monitoring absensi oleh PIC Absensi; Tidak dapat dilakukan pengecekan pemakaian dan sisa cuti karyawan, karena PIC Absensi tidak memiliki akses untuk menarik data pemakaian dan sisa cuti karyawan pada HCMS | G34: F | H34: 2 | I34: 4 | J34: 8
A35: 2022 | B35: SH1 | C35: Century21 | D35: HRD | E35: Absensi (setiap karyawan harus melakukan absensi setiap harinya, apabila tidak absen harus didukung dengan form ijin/cuti/tugas kantor yang disetujui atasan ybs) | F35: Berdasarkan sample check atas 6 bulan pembayaran Tunjangan Transport di mana untuk pembayaran bulan Okt’21 dilakukan sample ke data tarikan absensi, ditemukan seluruh pembayaran tunjangan transport tidak dilampirkan dengan data tarikan absensi; Terdapat perbedaan jumlah hari kerja atas 4 karyawan yang mendapatkan tunjangan transport antara yang tercatat di data rekapan untuk pembayaran Tunjangan Transport dengan data tarikan absensi di bulan Okt’21 | G35: F | H35: 2 | I35: 4 | J35: 8
A36: 2022 | B36: SH1 | C36: Century21 | D36: HRD | E36: Biaya Pengobatan (untuk biaya pengobatan yang menjadi tanggungan manajemen harus dikontrol dengan baik agar reimburse sesuai ketentuan dan tidak ada karyawan yang over plafond) | F36: Berdasarkan full check atas 1 karyawan yang mengajukan claim persalinan, ditemukan klaim penggantian biaya persalinan yang lebih besar dari ketentuan di mana seharusnya hanya sebesar 85% dari nilai kuitansi namun terbayar 100% dari nilai kuitansi | G36: F | H36: 2 | I36: 3 | J36: 6
A37: 2022 | B37: SH1 | C37: Century21 | D37: HRD | E37: Biaya Pengobatan (untuk biaya pengobatan yang menjadi tanggungan manajemen harus dikontrol dengan baik agar reimburse sesuai ketentuan dan tidak ada karyawan yang over plafond) | F37: Berdasarkan full check atas 20 pembayaran Asuransi Karyawan (Mandiri Inhealth), ditemukan 2 karyawan yang menerima benefit asuransi tidak sesuai dengan golongan karyawan yang bersangkutan | G37: F | H37: 2 | I37: 3 | J37: 6
A38: 2022 | B38: SH1 | C38: Century21 | D38: HRD | E38: Biaya Pengobatan (untuk biaya pengobatan yang menjadi tanggungan manajemen harus dikontrol dengan baik agar reimburse sesuai ketentuan dan tidak ada karyawan yang over plafond) | F38: Berdasarkan full check atas 20 pembayaran BPJS Kesehatan selama tahun 2021 ditemukan 9 karyawan yang BPJS kesehatannya tidak dibayarkan berselang 4 bulan s/d 59 bulan sejak deadline awal BPJS seharusnya dibayarkan dari tanggal masuk sampai dengan tanggal cut off audit 31 Des’2021; 3 karyawan yang BPJS kesehatannya mengikuti pembayaran BPJS suami, namun tidak dilengkapi dengan surat keterangan yang menjelaskan ybs mengikuti pembayaran BPJS suami | G38: F | H38: 2 | I38: 3 | J38: 6
A39: 2022 | B39: SH1 | C39: Century21 | D39: HRD | E39: Clearence Exit (HRD harus mengontrol serah terima baik pekerjaan maupun inventaris dari setiap karyawan yang mau mengudurkan diri). | G39: NF | H39: 0 | I39: 0 | J39: 0
A40: 2022 | B40: SH1 | C40: Century21 | D40: HRD | E40: Training ((Fasilitas training seharusnya diberikan kepada karyawan yang memenuhi syarat dan biaya yang dikeluarkan tidak melebihi budget; Terdapat sertifikat atas setiap training yang diikuti sebagai bukti keikutsertaan dalam training). | G40: NF | H40: 0 | I40: 0 | J40: 0
A41: 2022 | B41: SH1 | C41: Century21 | D41: HRD | E41: Karyawan kontrak dan pengelolaannya (kontrak karyawan harus sesuai dengan ketentuan yang berlaku yaitu maksimal 2x kontrak dengan masa kontrak 3 tahun yang dimana kontrak kedua maksimum 1 tahun; kontrak yang ada masih valid/belum expired; mutasi/promosi harus didukung dengan IM yang disetujui yang berwenang) | F41: Berdasarkan full check atas 10 karyawan Departemen Marketing yang bekerja selama periode Jan’21 s/d Des’21, ditemukan 7 kontrak karyawan yang telah expired namun belum dibuatkan perpanjangan kontrak, di mana 2 kontrak telah berakhir berkisar 205 hari dan 219 hari dan 5 kontrak belum diperpanjang berkisar 13 hari s/d 193 hari dari tanggal berakhir kontrak s/d tanggal karyawan tersebut resigned; Hasil evaluasi sales yang hanya secara lisan dan tidak dibuatkan secara tertulis, padahal sales tidak mencapai target penjualan dan seharusnya sudah berakhir di bulan ketiga | G41: F | H41: 2 | I41: 2 | J41: 4
A42: 2024 | B42: SH1 | C42: Ciputra Artpreneur | D42: Departemen Marketing | E42: Transaksi Penjualan patung/ souvenir/ penyewaan ruangan/ penyewaan space, dll: (harga jual yang dikenakan harus sesuai dengan PL, setiap keringanan yang diberikan (diskon harga maupun kelonggaran cara bayar) harus didukung persetujuan yang berwenang sesuai koridor). | G42: NF | H42: 0 | I42: 0 | J42: 0
A43: 2024 | B43: SH1 | C43: Ciputra Artpreneur | D43: Departemen Marketing | E43: Penerbitan Surat Pemesanan/ Surat Perjanjian atas pemesanan patung, sewa ruang, dan penerimaan lainnya: (pemesanan patung/ souvenir/ sewa ruang/ event sebaiknya didukung dengan Surat Pemesanan yang bernomor urut tercetak yang mencantumkan jenis patung, dan opsi-opsi lainnya seperti akan dilapis warna apa, ada plat nama atua tidak, dll serta ditandatangani kedua belah pihak). | G43: NF | H43: 0 | I43: 0 | J43: 0
...

Sheet Proyek
A1: No | B1: SH | C1: Project | D1: Total | E1: Finding | F1: Non-Finding | G1: Type | H1: Subtype | I1: Description
A2: 1 | B2: SH2 | C2: Asuransi Ciputra Life | D2: =COUNTIF(Master!C:C,Proyek!C2) -> 55 | E2: =COUNTIFS(Master!C:C,Proyek!C2,Master!G:G,"F") -> 23 | F2: =COUNTIFS(Master!C:C,Proyek!C2,Master!G:G,"NF") -> 32 | G2: Others | H2: Insurance
A3: 2 | B3: SH2 | C3: Bizpark 3 Bekasi | D3: =COUNTIF(Master!C:C,Proyek!C3) -> 32 | E3: =COUNTIFS(Master!C:C,Proyek!C3,Master!G:G,"F") -> 6 | F3: =COUNTIFS(Master!C:C,Proyek!C3,Master!G:G,"NF") -> 26 | G3: Residential | H3: Landed House
A4: 4 | B4: SH2 | C4: Bizpark Pulogadung | D4: =COUNTIF(Master!C:C,Proyek!C4) -> 67 | E4: =COUNTIFS(Master!C:C,Proyek!C4,Master!G:G,"F") -> 26 | F4: =COUNTIFS(Master!C:C,Proyek!C4,Master!G:G,"NF") -> 41 | G4: Residential | H4: Landed House
A5: 5 | B5: SH4 | C5: C Derma CWJ | D5: =COUNTIF(Master!C:C,Proyek!C5) -> 24 | E5: =COUNTIFS(Master!C:C,Proyek!C5,Master!G:G,"F") -> 11 | F5: =COUNTIFS(Master!C:C,Proyek!C5,Master!G:G,"NF") -> 13 | G5: Healthcare | H5: Clinic
A6: 6 | B6: SH1 | C6: Century21 | D6: =COUNTIF(Master!C:C,Proyek!C6) -> 40 | E6: =COUNTIFS(Master!C:C,Proyek!C6,Master!G:G,"F") -> 23 | F6: =COUNTIFS(Master!C:C,Proyek!C6,Master!G:G,"NF") -> 17 | G6: Others | H6: Broker
A7: 7 | B7: SH1 | C7: Ciputra Artpreneur | D7: =COUNTIF(Master!C:C,Proyek!C7) -> 27 | E7: =COUNTIFS(Master!C:C,Proyek!C7,Master!G:G,"F") -> 16 | F7: =COUNTIFS(Master!C:C,Proyek!C7,Master!G:G,"NF") -> 11 | G7: Others | H7: Theatre
A8: 8 | B8: SH3A | C8: Ciputra Beach Resort | D8: =COUNTIF(Master!C:C,Proyek!C8) -> 49 | E8: =COUNTIFS(Master!C:C,Proyek!C8,Master!G:G,"F") -> 27 | F8: =COUNTIFS(Master!C:C,Proyek!C8,Master!G:G,"NF") -> 22 | G8: Residential | H8: Landed House
A9: 9 | B9: SH4 | C9: Ciputra Hospital Citra Garden City | D9: =COUNTIF(Master!C:C,Proyek!C9) -> 120 | E9: =COUNTIFS(Master!C:C,Proyek!C9,Master!G:G,"F") -> 74 | F9: =COUNTIFS(Master!C:C,Proyek!C9,Master!G:G,"NF") -> 46 | G9: Healthcare | H9: Hospital
A10: 10 | B10: SH4 | C10: Ciputra Hospital Citra Raya Tangerang | D10: =COUNTIF(Master!C:C,Proyek!C10) -> 146 | E10: =COUNTIFS(Master!C:C,Proyek!C10,Master!G:G,"F") -> 83 | F10: =COUNTIFS(Master!C:C,Proyek!C10,Master!G:G,"NF") -> 63 | G10: Healthcare | H10: Hospital
A11: 11 | B11: SH3A | C11: Ciputra Hospitality (Citra Dream HO) | D11: =COUNTIF(Master!C:C,Proyek!C11) -> 17 | E11: =COUNTIFS(Master!C:C,Proyek!C11,Master!G:G,"F") -> 10 | F11: =COUNTIFS(Master!C:C,Proyek!C11,Master!G:G,"NF") -> 7 | G11: Commercial | H11: Office
A12: 12 | B12: SH3A | C12: Ciputra International Puri | D12: =COUNTIF(Master!C:C,Proyek!C12) -> 97 | E12: =COUNTIFS(Master!C:C,Proyek!C12,Master!G:G,"F") -> 52 | F12: =COUNTIFS(Master!C:C,Proyek!C12,Master!G:G,"NF") -> 45 | G12: Commercial | H12: Office, Apartment, Hotel | I12: Ciputra International Puri merupakan proyek pengembangan mixed-use dari PT Ciputra Property (anak perusahaan) yang terletak di kawasan strategis Jakarta Barat dan mudah diakses dari Bandara Internasional Soekarno-Hatta. Diluncurkan pada tahun 2014, proyek ini memiliki luas lahan sampai dengan 7,5 hektar. Ciputra International Puri akan mengembangkan 10 tower, yang terdiri dari 6 gedung perkantoran, 3 hunian bertingkat, dan 1 hotel. Perencanaan yang baik, konektivitas antar tower yang mudah, serta desain yang mewah dan modern akan semakin menambah tingkat kenyamanan dan eksklusif dari kawasan superblok ini.
A13: 13 | B13: SH4 | C13: Ciputra Medical Center (CMC) | D13: =COUNTIF(Master!C:C,Proyek!C13) -> 99 | E13: =COUNTIFS(Master!C:C,Proyek!C13,Master!G:G,"F") -> 52 | F13: =COUNTIFS(Master!C:C,Proyek!C13,Master!G:G,"NF") -> 47 | G13: Healthcare | H13: Clinic
A14: 14 | B14: SH4 | C14: Ciputra Mitra Hospital | D14: =COUNTIF(Master!C:C,Proyek!C14) -> 44 | E14: =COUNTIFS(Master!C:C,Proyek!C14,Master!G:G,"F") -> 25 | F14: =COUNTIFS(Master!C:C,Proyek!C14,Master!G:G,"NF") -> 19 | G14: Healthcare | H14: Hospital
A15: 15 | B15: SH4 | C15: Ciputra SMG Eye Clinic | D15: =COUNTIF(Master!C:C,Proyek!C15) -> 35 | E15: =COUNTIFS(Master!C:C,Proyek!C15,Master!G:G,"F") -> 15 | F15: =COUNTIFS(Master!C:C,Proyek!C15,Master!G:G,"NF") -> 20 | G15: Healthcare | H15: Clinic
A16: 16 | B16: SH2 | C16: Ciputra Surabaya Padang Golf | D16: =COUNTIF(Master!C:C,Proyek!C16) -> 132 | E16: =COUNTIFS(Master!C:C,Proyek!C16,Master!G:G,"F") -> 57 | F16: =COUNTIFS(Master!C:C,Proyek!C16,Master!G:G,"NF") -> 75 | G16: Commercial | H16: Golf Course, Family Club, Wedding | I16: Ciputra Golf & Family Club Surabaya is the biggest and the most complete golf course in East Java, designed by Andy Dye from Dye Design Corp., a reputable golf course designer in the world. The designer took advantage of the range of elevation in developing the course. Following the natural hill and valley topography of the area, the course is designed stadium style with the holes in the valley.
A17: 17 | B17: SH2 | C17: Ciputra The Taman Dayu | D17: =COUNTIF(Master!C:C,Proyek!C17) -> 131 | E17: =COUNTIFS(Master!C:C,Proyek!C17,Master!G:G,"F") -> 38 | F17: =COUNTIFS(Master!C:C,Proyek!C17,Master!G:G,"NF") -> 93 | G17: Residential | H17: Landed House
A18: 18 | B18: SH3A | C18: Ciputra World Jakarta 1 | D18: =COUNTIF(Master!C:C,Proyek!C18) -> 38 | E18: =COUNTIFS(Master!C:C,Proyek!C18,Master!G:G,"F") -> 28 | F18: =COUNTIFS(Master!C:C,Proyek!C18,Master!G:G,"NF") -> 10 | G18: Commercial | H18: Mall, Office
A19: 19 | B19: SH3A | C19: Ciputra World Jakarta 2 | D19: =COUNTIF(Master!C:C,Proyek!C19) -> 44 | E19: =COUNTIFS(Master!C:C,Proyek!C19,Master!G:G,"F") -> 20 | F19: =COUNTIFS(Master!C:C,Proyek!C19,Master!G:G,"NF") -> 24 | G19: Commercial | H19: Mall, Office
A20: 20 | B20: SH2 | C20: Ciputra World Surabaya Apartment | D20: =COUNTIF(Master!C:C,Proyek!C20) -> 91 | E20: =COUNTIFS(Master!C:C,Proyek!C20,Master!G:G,"F") -> 48 | F20: =COUNTIFS(Master!C:C,Proyek!C20,Master!G:G,"NF") -> 43 | G20: Commercial | H20: Apartment
A21: 21 | B21: SH2 | C21: Ciputra World Surabaya Hotel | D21: =COUNTIF(Master!C:C,Proyek!C21) -> 101 | E21: =COUNTIFS(Master!C:C,Proyek!C21,Master!G:G,"F") -> 50 | F21: =COUNTIFS(Master!C:C,Proyek!C21,Master!G:G,"NF") -> 51 | G21: Commercial | H21: Hotel
A22: 22 | B22: SH2 | C22: Ciputra World Surabaya Mall | D22: =COUNTIF(Master!C:C,Proyek!C22) -> 86 | E22: =COUNTIFS(Master!C:C,Proyek!C22,Master!G:G,"F") -> 52 | F22: =COUNTIFS(Master!C:C,Proyek!C22,Master!G:G,"NF") -> 34 | G22: Commercial | H22: Mall
A23: 23 | B23: SH3A | C23: Citra Beach Resort | D23: =COUNTIF(Master!C:C,Proyek!C23) -> 46 | E23: =COUNTIFS(Master!C:C,Proyek!C23,Master!G:G,"F") -> 22 | F23: =COUNTIFS(Master!C:C,Proyek!C23,Master!G:G,"NF") -> 24 | G23: Residential | H23: Landed House | I23: Ciputra Beach Resort terletak di Kabupaten Tabanan, Bali, membentang di atas tanah seluas 80 hektar dan garis pantai sepanjang 1,7 km. Dilengkapi oleh pemandangan laut yang mengagumkan serta pegunungan dan teras sawah, ombak berselancar yang terkenal, serta ciri khas sejarah dan kultur yang kental, Kabupaten Tabanan menawarkan pengalaman yang tak terlupakan yang hanya didapatkan di pulau Bali. Hanya 45 menit dari bandara, Ciputra Beach Resort akan menawarkan pengalaman khusus dari pulau Bali melalui resor dan hunian mewah. Ciputra Beach Resort terdiri dari beberapa cluster seperti Sadana, Nivata, dan akan mengembangkan dua tahap dan menghadirkan dua operator kelas dunia yaitu The Ritz-Carlton dan Rosewood Hotels & Resorts.
A24: 24 | B24: SH1 | C24: Citra City Balikpapan | D24: =COUNTIF(Master!C:C,Proyek!C24) -> 44 | E24: =COUNTIFS(Master!C:C,Proyek!C24,Master!G:G,"F") -> 19 | F24: =COUNTIFS(Master!C:C,Proyek!C24,Master!G:G,"NF") -> 25 | G24: Residential | H24: Landed House | I24: Citra City Balikpapan dikembangkan di atas masterplan premium seluas 9 hektar, dengan visi untuk menjadi city lifestyle center yang mendukung gaya hidup modern. Hadir dengan konsep one stop living, kawasan ini memungkinkan penghuninya merasakan kenyamanan hunian, kemudahan akses ke berbagai fasilitas, dan dukungan penuh bagi kebutuhan hidup sehari-hari dalam satu area yang terintegrasi. Kawasan ini memadukan area residensial premium dengan area komersial, menjadikannya pilihan menarik bagi mereka yang mencari perumahan di Balikpapan yang memiliki potensi nilai investasi yang terus berkembang. Baik untuk tempat tinggal maupun investasi, Citra City Balikpapan menawarkan suasana lingkungan yang menyatukan kualitas hidup dan peluang ekonomi di gerbang menuju Ibu Kota Nusantara (IKN). Masterplan Citra City Balikpapan mengusung semangat “masterpiece of prime living in the city,” menawarkan lingkungan hunian yang tak hanya fungsional, tetapi juga penuh nilai estetika dan kenyamanan. Setiap detail kawasan ini didesain untuk menciptakan standar hidup yang tinggi dan memenuhi kebutuhan masyarakat urban di Balikpapan. Dirancang dengan green concept, kawasan ini menghadirkan lingkungan bisnis dan hiburan yang eco-friendly atau ramah lingkungan. Kehadiran ruang hijau dan taman tematik tidak hanya menciptakan udara segar tetapi juga memberikan kesempatan bagi penghuni untuk menjalani gaya hidup yang lebih sehat dan berkualitas. Semua ini dipersembahkan agar Anda mendapatkan gaya hidup yang lebih baik, sejalan dengan konsep sustainable development yang menjadi prinsip dasar Ciputra Group dalam mengembangkan Citra City Balikpapan.
A25: 25 | B25: SH1 | C25: Citra City Sentul | D25: =COUNTIF(Master!C:C,Proyek!C25) -> 37 | E25: =COUNTIFS(Master!C:C,Proyek!C25,Master!G:G,"F") -> 19 | F25: =COUNTIFS(Master!C:C,Proyek!C25,Master!G:G,"NF") -> 18 | G25: Residential | H25: Landed House
A26: 26 | B26: SH3A | C26: Hotel Citra Dream Bintaro | D26: =COUNTIF(Master!C:C,Proyek!C26) -> 93 | E26: =COUNTIFS(Master!C:C,Proyek!C26,Master!G:G,"F") -> 47 | F26: =COUNTIFS(Master!C:C,Proyek!C26,Master!G:G,"NF") -> 46 | G26: Commercial | H26: Hotel
A27: 27 | B27: SH3A | C27: Hotel Citra Dream Yogyakarta | D27: =COUNTIF(Master!C:C,Proyek!C27) -> 97 | E27: =COUNTIFS(Master!C:C,Proyek!C27,Master!G:G,"F") -> 62 | F27: =COUNTIFS(Master!C:C,Proyek!C27,Master!G:G,"NF") -> 35 | G27: Commercial | H27: Hotel
A28: 28 | B28: SH1 | C28: Citra Garden Bintaro | D28: =COUNTIF(Master!C:C,Proyek!C28) -> 37 | E28: =COUNTIFS(Master!C:C,Proyek!C28,Master!G:G,"F") -> 26 | F28: =COUNTIFS(Master!C:C,Proyek!C28,Master!G:G,"NF") -> 11 | G28: Residential | H28: Landed House
A29: 29 | B29: SH1 | C29: Citra Garden BMW Cilegon | D29: =COUNTIF(Master!C:C,Proyek!C29) -> 131 | E29: =COUNTIFS(Master!C:C,Proyek!C29,Master!G:G,"F") -> 53 | F29: =COUNTIFS(Master!C:C,Proyek!C29,Master!G:G,"NF") -> 78 | G29: Residential | H29: Landed House
A30: 30 | B30: SH1 | C30: Citra Garden Malang | D30: =COUNTIF(Master!C:C,Proyek!C30) -> 45 | E30: =COUNTIFS(Master!C:C,Proyek!C30,Master!G:G,"F") -> 16 | F30: =COUNTIFS(Master!C:C,Proyek!C30,Master!G:G,"NF") -> 29 | G30: Residential | H30: Landed House
A31: 31 | B31: SH1 | C31: Citra Garden Puri Jakarta | D31: =COUNTIF(Master!C:C,Proyek!C31) -> 58 | E31: =COUNTIFS(Master!C:C,Proyek!C31,Master!G:G,"F") -> 31 | F31: =COUNTIFS(Master!C:C,Proyek!C31,Master!G:G,"NF") -> 27 | G31: Residential | H31: Landed House
A32: 32 | B32: SH1 | C32: Citra Garden Serpong | D32: =COUNTIF(Master!C:C,Proyek!C32) -> 41 | E32: =COUNTIFS(Master!C:C,Proyek!C32,Master!G:G,"F") -> 26 | F32: =COUNTIFS(Master!C:C,Proyek!C32,Master!G:G,"NF") -> 15 | G32: Residential | H32: Landed House
A33: 33 | B33: SH2 | C33: Citra Garden Sidoarjo | D33: =COUNTIF(Master!C:C,Proyek!C33) -> 146 | E33: =COUNTIFS(Master!C:C,Proyek!C33,Master!G:G,"F") -> 55 | F33: =COUNTIFS(Master!C:C,Proyek!C33,Master!G:G,"NF") -> 91 | G33: Residential | H33: Landed House
A34: 34 | B34: SH2 | C34: Citra Grand CBD Cibubur | D34: =COUNTIF(Master!C:C,Proyek!C34) -> 48 | E34: =COUNTIFS(Master!C:C,Proyek!C34,Master!G:G,"F") -> 12 | F34: =COUNTIFS(Master!C:C,Proyek!C34,Master!G:G,"NF") -> 36 | G34: Residential | H34: Landed House
A35: 35 | B35: SH2 | C35: Citra Grand Semarang | D35: =COUNTIF(Master!C:C,Proyek!C35) -> 202 | E35: =COUNTIFS(Master!C:C,Proyek!C35,Master!G:G,"F") -> 78 | F35: =COUNTIFS(Master!C:C,Proyek!C35,Master!G:G,"NF") -> 124 | G35: Residential | H35: Landed House
A36: 36 | B36: SH2 | C36: Citra Harmoni Sidoarjo | D36: =COUNTIF(Master!C:C,Proyek!C36) -> 141 | E36: =COUNTIFS(Master!C:C,Proyek!C36,Master!G:G,"F") -> 57 | F36: =COUNTIFS(Master!C:C,Proyek!C36,Master!G:G,"NF") -> 84 | G36: Residential | H36: Landed House
... A112: 112 | B112: SH3B | C112: Vidaview Apartment | D112: =COUNTIF(Master!C:C,Proyek!C112) -> 45 | E112: =COUNTIFS(Master!C:C,Proyek!C112,Master!G:G,"F") -> 20 | F112: =COUNTIFS(Master!C:C,Proyek!C112,Master!G:G,"NF") -> 25 | G112: Commercial | H112: Apartment
